Workbook
Name ListLinks: _xludf.links()

Sheet Dashboard
C2: Dashboard - Dépréciation des Créances Clients
C4: Overview KPIs | J4: Evolution de la Provision sur les 12 dernies mois
C6: Créances Client | D6: Total Provision | E6: % Dépréciation | F6: #Nbre Factures | G6: #Nbre Clients
C7: =Calcul!D64/1000000 -> 79783.81 | D7: =Calcul!D65/1000000 -> 11461.991 | E7: =Calcul!D66 -> 0.14366312 | F7: =Calcul!D67 -> 2457 | G7: =Calcul!D68 -> 578
C8: =Calcul!F64 -> 0.16095407 | D8: =Calcul!F65 -> 0.13107001
C10: Provision de dépréciation par Age
C12: Total Provision | G12: =D7 -> 11461.991
C13: [1-30 jrs | G13: =Calcul!D73/1000000 -> 1634.3193
C14: [31-60 jrs | G14: =Calcul!E73/1000000 -> 0
C15: [61-90 jrs | G15: =Calcul!F73/1000000 -> 1431.5681
C16: [91-120 jrs | G16: =Calcul!G73/1000000 -> 1679.7696
C17: [120 + jrs | G17: =Calcul!H73/1000000 -> 5494.3623
C19: Total de la provision par Segment de clients | J19: Provision par segment (Clients)

Sheet Matrice
B4: Taux de Pertes Historques
B7: DelaiKey | C7: DelaiGroup | D7: MinDelai | E7: MaxDelai | F7: Taux
B8: 1 | C8: Not Overdue | D8: -3000 | E8: 0 | F8: 0.06
B9: 2 | C9: Overdue 1-30 jrs | D9: 0 | E9: 30 | F9: 0.08
B10: 3 | C10: Overdue 31-60 jrs | D10: 30 | E10: 60 | F10: 0.096
B11: 4 | C11: Overdue 61-90 jrs | D11: 60 | E11: 90 | F11: 0.124
B12: 5 | C12: Overdue 91-120 jrs | D12: 90 | E12: 120 | F12: 0.184
B13: 6 | C13: Overdue 120 + jrs | D13: 120 | E13: 999999999 | F13: 0.3

Sheet Calcul
B2: Change Requests - Control
C4: 13
W5: Date
B6: Mois Actuel | C6: =VLOOKUP(C4,$V$6:$X$67,3,0) -> 43524 | V6: 1 | W6: =TEXT(X6,"MMM-AAAA") -> févr-2018 | X6: 43159
V7: =V6+1 -> 2 | W7: =TEXT(X7,"MMM-AAAA") -> mars-2018 | X7: 43190
B8: Calculations / Consolidation | V8: =V7+1 -> 3 | W8: =TEXT(X8,"MMM-AAAA") -> avr-2018 | X8: 43220
D9: RAP | E9: Provision | G9: #Nb Factures | H9: NbClient | V9: =V8+1 -> 4 | W9: =TEXT(X9,"MMM-AAAA") -> mai-2018 | X9: 43251
D10: KPI | K10: Segment | V10: =V9+1 -> 5 | W10: =TEXT(X10,"MMM-AAAA") -> juin-2018 | X10: 43281
B11: Fun du Mois | C11: Mois | D11: Total Créances | E11: Total Provision | F11: % Déprciation | G11: NB Factures | H11: Nb Clients | K11: Segment 1 | L11: Segment 2 | M11: Segment 3 | N11: Segment 4 | O11: Segment 5 | P11: Segment 6 | V11: =V10+1 -> 6 | W11: =TEXT(X11,"MMM-AAAA") -> juil-2018 | X11: 43312
K12: =GETPIVOTDATA("[Measures].[Provision]",PivotTable!$B$3,"[Dates].[MMM-YYYY]","[Dates].[MMM-YYYY].&["&$C13&"]","[CreanceData].[SEGMENT1]","[CreanceData].[SEGMENT1].&[Segment 1]") -> 12448358 | V12: =V11+1 -> 7 | W12: =TEXT(X12,"MMM-AAAA") -> août-2018 | X12: 43343
A13: 1 | B13: =EOMONTH(B14,-1) -> 43190 | C13: =TEXT(B13,"MMM-AAAA") -> mars-2018 | D13: =GETPIVOTDATA("[Measures].["&D$9&"]",PivotTable!$B$3,"[Dates].[MMM-YYYY]","[Dates].[MMM-YYYY].&["&$C13&"]") -> 18835091761 | E13: =GETPIVOTDATA("[Measures].["&E$9&"]",PivotTable!$B$3,"[Dates].[MMM-YYYY]","[Dates].[MMM-YYYY].&["&$C13&"]") -> 3.186612e+09 | F13: =E13/D13 -> 0.16918484 | G13: =GETPIVOTDATA("[Measures].["&G$9&"]",PivotTable!$B$3,"[Dates].[MMM-YYYY]","[Dates].[MMM-YYYY].&["&$C13&"]") -> 450 | H13: =GETPIVOTDATA("[Measures].["&H$9&"]",PivotTable!$B$3,"[Dates].[MMM-YYYY]","[Dates].[MMM-YYYY].&["&$C13&"]") -> 140 | K13: =IFERROR(GETPIVOTDATA("[Measures].[Provision]",PivotTable!$B$3,"[Dates].[MMM-YYYY]","[Dates].[MMM-YYYY].&["&$C13&"]","[Creancedata].[SEGMENT1]","[Creancedata].[SEGMENT1].&["&K$11&"]"),0)/1000000 -> 12.448358 | L13: =IFERROR(GETPIVOTDATA("[Measures].[Provision]",PivotTable!$B$3,"[Dates].[MMM-YYYY]","[Dates].[MMM-YYYY].&["&$C13&"]","[Creancedata].[SEGMENT1]","[Creancedata].[SEGMENT1].&["&L$11&"]"),0)/1000000 -> 79.830863 | M13: =IFERROR(GETPIVOTDATA("[Measures].[Provision]",PivotTable!$B$3,"[Dates].[MMM-YYYY]","[Dates].[MMM-YYYY].&["&$C13&"]","[Creancedata].[SEGMENT1]","[Creancedata].[SEGMENT1].&["&M$11&"]"),0)/1000000 -> 8.4734669 | N13: =IFERROR(GETPIVOTDATA("[Measures].[Provision]",PivotTable!$B$3,"[Dates].[MMM-YYYY]","[Dates].[MMM-YYYY].&["&$C13&"]","[Creancedata].[SEGMENT1]","[Creancedata].[SEGMENT1].&["&N$11&"]"),0)/1000000 -> 1920.2233 | O13: =IFERROR(GETPIVOTDATA("[Measures].[Provision]",PivotTable!$B$3,"[Dates].[MMM-YYYY]","[Dates].[MMM-YYYY].&["&$C13&"]","[Creancedata].[SEGMENT1]","[Creancedata].[SEGMENT1].&["&O$11&"]"),0)/1000000 -> 0 | P13: =IFERROR(GETPIVOTDATA("[Measures].[Provision]",PivotTable!$B$3,"[Dates].[MMM-YYYY]","[Dates].[MMM-YYYY].&["&$C13&"]","[Creancedata].[SEGMENT1]","[Creancedata].[SEGMENT1].&["&P$11&"]"),0)/1000000 -> 1165.636 | R13: =E13/1000000 -> 3186.612 | V13: =V12+1 -> 8 | W13: =TEXT(X13,"MMM-AAAA") -> sept-2018 | X13: 43373
A14: =1+A13 -> 2 | B14: =EOMONTH(B15,-1) -> 43220 | C14: =TEXT(B14,"MMM-AAAA") -> avr-2018 | D14: =GETPIVOTDATA("[Measures].["&D$9&"]",PivotTable!$B$3,"[Dates].[MMM-YYYY]","[Dates].[MMM-YYYY].&["&$C14&"]") -> 22231742939 | E14: =GETPIVOTDATA("[Measures].["&E$9&"]",PivotTable!$B$3,"[Dates].[MMM-YYYY]","[Dates].[MMM-YYYY].&["&$C14&"]") -> 3.8853683e+09 | F14: =E14/D14 -> 0.1747667 | G14: =GETPIVOTDATA("[Measures].["&G$9&"]",PivotTable!$B$3,"[Dates].[MMM-YYYY]","[Dates].[MMM-YYYY].&["&$C14&"]") -> 571 | H14: =GETPIVOTDATA("[Measures].["&H$9&"]",PivotTable!$B$3,"[Dates].[MMM-YYYY]","[Dates].[MMM-YYYY].&["&$C14&"]") -> 157 | K14: =IFERROR(GETPIVOTDATA("[Measures].[Provision]",PivotTable!$B$3,"[Dates].[MMM-YYYY]","[Dates].[MMM-YYYY].&["&$C14&"]","[Creancedata].[SEGMENT1]","[Creancedata].[SEGMENT1].&["&K$11&"]"),0)/1000000 -> 38.449908 | L14: =IFERROR(GETPIVOTDATA("[Measures].[Provision]",PivotTable!$B$3,"[Dates].[MMM-YYYY]","[Dates].[MMM-YYYY].&["&$C14&"]","[Creancedata].[SEGMENT1]","[Creancedata].[SEGMENT1].&["&L$11&"]"),0)/1000000 -> 63.486014 | M14: =IFERROR(GETPIVOTDATA("[Measures].[Provision]",PivotTable!$B$3,"[Dates].[MMM-YYYY]","[Dates].[MMM-YYYY].&["&$C14&"]","[Creancedata].[SEGMENT1]","[Creancedata].[SEGMENT1].&["&M$11&"]"),0)/1000000 -> 47.037168 | N14: =IFERROR(GETPIVOTDATA("[Measures].[Provision]",PivotTable!$B$3,"[Dates].[MMM-YYYY]","[Dates].[MMM-YYYY].&["&$C14&"]","[Creancedata].[SEGMENT1]","[Creancedata].[SEGMENT1].&["&N$11&"]"),0)/1000000 -> 2423.579 | O14: =IFERROR(GETPIVOTDATA("[Measures].[Provision]",PivotTable!$B$3,"[Dates].[MMM-YYYY]","[Dates].[MMM-YYYY].&["&$C14&"]","[Creancedata].[SEGMENT1]","[Creancedata].[SEGMENT1].&["&O$11&"]"),0)/1000000 -> 0 | P14: =IFERROR(GETPIVOTDATA("[Measures].[Provision]",PivotTable!$B$3,"[Dates].[MMM-YYYY]","[Dates].[MMM-YYYY].&["&$C14&"]","[Creancedata].[SEGMENT1]","[Creancedata].[SEGMENT1].&["&P$11&"]"),0)/1000000 -> 1312.8161 | R14: =E14/1000000 -> 3885.3683 | V14: =V13+1 -> 9 | W14: =TEXT(X14,"MMM-AAAA") -> oct-2018 | X14: 43404
A15: =1+A14 -> 3 | B15: =EOMONTH(B16,-1) -> 43251 | C15: =TEXT(B15,"MMM-AAAA") -> mai-2018 | D15: =GETPIVOTDATA("[Measures].["&D$9&"]",PivotTable!$B$3,"[Dates].[MMM-YYYY]","[Dates].[MMM-YYYY].&["&$C15&"]") -> 16198776172 | E15: =GETPIVOTDATA("[Measures].["&E$9&"]",PivotTable!$B$3,"[Dates].[MMM-YYYY]","[Dates].[MMM-YYYY].&["&$C15&"]") -> 2.7971895e+09 | F15: =E15/D15 -> 0.17267906 | G15: =GETPIVOTDATA("[Measures].["&G$9&"]",PivotTable!$B$3,"[Dates].[MMM-YYYY]","[Dates].[MMM-YYYY].&["&$C15&"]") -> 670 | H15: =GETPIVOTDATA("[Measures].["&H$9&"]",PivotTable!$B$3,"[Dates].[MMM-YYYY]","[Dates].[MMM-YYYY].&["&$C15&"]") -> 176 | K15: =IFERROR(GETPIVOTDATA("[Measures].[Provision]",PivotTable!$B$3,"[Dates].[MMM-YYYY]","[Dates].[MMM-YYYY].&["&$C15&"]","[Creancedata].[SEGMENT1]","[Creancedata].[SEGMENT1].&["&K$11&"]"),0)/1000000 -> 29.01515 | L15: =IFERROR(GETPIVOTDATA("[Measures].[Provision]",PivotTable!$B$3,"[Dates].[MMM-YYYY]","[Dates].[MMM-YYYY].&["&$C15&"]","[Creancedata].[SEGMENT1]","[Creancedata].[SEGMENT1].&["&L$11&"]"),0)/1000000 -> 84.916265 | M15: =IFERROR(GETPIVOTDATA("[Measures].[Provision]",PivotTable!$B$3,"[Dates].[MMM-YYYY]","[Dates].[MMM-YYYY].&["&$C15&"]","[Creancedata].[SEGMENT1]","[Creancedata].[SEGMENT1].&["&M$11&"]"),0)/1000000 -> 65.792731 | N15: =IFERROR(GETPIVOTDATA("[Measures].[Provision]",PivotTable!$B$3,"[Dates].[MMM-YYYY]","[Dates].[MMM-YYYY].&["&$C15&"]","[Creancedata].[SEGMENT1]","[Creancedata].[SEGMENT1].&["&N$11&"]"),0)/1000000 -> 2427.7635 | O15: =IFERROR(GETPIVOTDATA("[Measures].[Provision]",PivotTable!$B$3,"[Dates].[MMM-YYYY]","[Dates].[MMM-YYYY].&["&$C15&"]","[Creancedata].[SEGMENT1]","[Creancedata].[SEGMENT1].&["&O$11&"]"),0)/1000000 -> 0 | P15: =IFERROR(GETPIVOTDATA("[Measures].[Provision]",PivotTable!$B$3,"[Dates].[MMM-YYYY]","[Dates].[MMM-YYYY].&["&$C15&"]","[Creancedata].[SEGMENT1]","[Creancedata].[SEGMENT1].&["&P$11&"]"),0)/1000000 -> 189.70181 | R15: =E15/1000000 -> 2797.1895 | V15: =V14+1 -> 10 | W15: =TEXT(X15,"MMM-AAAA") -> nov-2018 | X15: 43434
A16: =1+A15 -> 4 | B16: =EOMONTH(B17,-1) -> 43281 | C16: =TEXT(B16,"MMM-AAAA") -> juin-2018 | D16: =GETPIVOTDATA("[Measures].["&D$9&"]",PivotTable!$B$3,"[Dates].[MMM-YYYY]","[Dates].[MMM-YYYY].&["&$C16&"]") -> 20422167699 | E16: =GETPIVOTDATA("[Measures].["&E$9&"]",PivotTable!$B$3,"[Dates].[MMM-YYYY]","[Dates].[MMM-YYYY].&["&$C16&"]") -> 3.1561579e+09 | F16: =E16/D16 -> 0.15454568 | G16: =GETPIVOTDATA("[Measures].["&G$9&"]",PivotTable!$B$3,"[Dates].[MMM-YYYY]","[Dates].[MMM-YYYY].&["&$C16&"]") -> 798 | H16: =GETPIVOTDATA("[Measures].["&H$9&"]",PivotTable!$B$3,"[Dates].[MMM-YYYY]","[Dates].[MMM-YYYY].&["&$C16&"]") -> 196 | K16: =IFERROR(GETPIVOTDATA("[Measures].[Provision]",PivotTable!$B$3,"[Dates].[MMM-YYYY]","[Dates].[MMM-YYYY].&["&$C16&"]","[Creancedata].[SEGMENT1]","[Creancedata].[SEGMENT1].&["&K$11&"]"),0)/1000000 -> 337.3279 | L16: =IFERROR(GETPIVOTDATA("[Measures].[Provision]",PivotTable!$B$3,"[Dates].[MMM-YYYY]","[Dates].[MMM-YYYY].&["&$C16&"]","[Creancedata].[SEGMENT1]","[Creancedata].[SEGMENT1].&["&L$11&"]"),0)/1000000 -> 134.26087 | M16: =IFERROR(GETPIVOTDATA("[Measures].[Provision]",PivotTable!$B$3,"[Dates].[MMM-YYYY]","[Dates].[MMM-YYYY].&["&$C16&"]","[Creancedata].[SEGMENT1]","[Creancedata].[SEGMENT1].&["&M$11&"]"),0)/1000000 -> 68.891177 | N16: =IFERROR(GETPIVOTDATA("[Measures].[Provision]",PivotTable!$B$3,"[Dates].[MMM-YYYY]","[Dates].[MMM-YYYY].&["&$C16&"]","[Creancedata].[SEGMENT1]","[Creancedata].[SEGMENT1].&["&N$11&"]"),0)/1000000 -> 2346.4776 | O16: =IFERROR(GETPIVOTDATA("[Measures].[Provision]",PivotTable!$B$3,"[Dates].[MMM-YYYY]","[Dates].[MMM-YYYY].&["&$C16&"]","[Creancedata].[SEGMENT1]","[Creancedata].[SEGMENT1].&["&O$11&"]"),0)/1000000 -> 0.00101136 | P16: =IFERROR(GETPIVOTDATA("[Measures].[Provision]",PivotTable!$B$3,"[Dates].[MMM-YYYY]","[Dates].[MMM-YYYY].&["&$C16&"]","[Creancedata].[SEGMENT1]","[Creancedata].[SEGMENT1].&["&P$11&"]"),0)/1000000 -> 269.19928 | R16: =E16/1000000 -> 3156.1579 | V16: =V15+1 -> 11 | W16: =TEXT(X16,"MMM-AAAA") -> déc-2018 | X16: 43465
A17: =1+A16 -> 5 | B17: =EOMONTH(B18,-1) -> 43312 | C17: =TEXT(B17,"MMM-AAAA") -> juil-2018 | D17: =GETPIVOTDATA("[Measures].["&D$9&"]",PivotTable!$B$3,"[Dates].[MMM-YYYY]","[Dates].[MMM-YYYY].&["&$C17&"]") -> 22257403529 | E17: =GETPIVOTDATA("[Measures].["&E$9&"]",PivotTable!$B$3,"[Dates].[MMM-YYYY]","[Dates].[MMM-YYYY].&["&$C17&"]") -> 3.7610653e+09 | F17: =E17/D17 -> 0.16898042 | G17: =GETPIVOTDATA("[Measures].["&G$9&"]",PivotTable!$B$3,"[Dates].[MMM-YYYY]","[Dates].[MMM-YYYY].&["&$C17&"]") -> 922 | H17: =GETPIVOTDATA("[Measures].["&H$9&"]",PivotTable!$B$3,"[Dates].[MMM-YYYY]","[Dates].[MMM-YYYY].&["&$C17&"]") -> 212 | K17: =IFERROR(GETPIVOTDATA("[Measures].[Provision]",PivotTable!$B$3,"[Dates].[MMM-YYYY]","[Dates].[MMM-YYYY].&["&$C17&"]","[Creancedata].[SEGMENT1]","[Creancedata].[SEGMENT1].&["&K$11&"]"),0)/1000000 -> 408.20731 | L17: =IFERROR(GETPIVOTDATA("[Measures].[Provision]",PivotTable!$B$3,"[Dates].[MMM-YYYY]","[Dates].[MMM-YYYY].&["&$C17&"]","[Creancedata].[SEGMENT1]","[Creancedata].[SEGMENT1].&["&L$11&"]"),0)/1000000 -> 187.88532 | M17: =IFERROR(GETPIVOTDATA("[Measures].[Provision]",PivotTable!$B$3,"[Dates].[MMM-YYYY]","[Dates].[MMM-YYYY].&["&$C17&"]","[Creancedata].[SEGMENT1]","[Creancedata].[SEGMENT1].&["&M$11&"]"),0)/1000000 -> 113.25025 | N17: =IFERROR(GETPIVOTDATA("[Measures].[Provision]",PivotTable!$B$3,"[Dates].[MMM-YYYY]","[Dates].[MMM-YYYY].&["&$C17&"]","[Creancedata].[SEGMENT1]","[Creancedata].[SEGMENT1].&["&N$11&"]"),0)/1000000 -> 2804.3752 | O17: =IFERROR(GETPIVOTDATA("[Measures].[Provision]",PivotTable!$B$3,"[Dates].[MMM-YYYY]","[Dates].[MMM-YYYY].&["&$C17&"]","[Creancedata].[SEGMENT1]","[Creancedata].[SEGMENT1].&["&O$11&"]"),0)/1000000 -> 10.51329 | P17: =IFERROR(GETPIVOTDATA("[Measures].[Provision]",PivotTable!$B$3,"[Dates].[MMM-YYYY]","[Dates].[MMM-YYYY].&["&$C17&"]","[Creancedata].[SEGMENT1]","[Creancedata].[SEGMENT1].&["&P$11&"]"),0)/1000000 -> 236.8339 | R17: =E17/1000000 -> 3761.0653 | V17: =V16+1 -> 12 | W17: =TEXT(X17,"MMM-AAAA") -> janv-2019 | X17: 43496
A18: =1+A17 -> 6 | B18: =EOMONTH(B19,-1) -> 43343 | C18: =TEXT(B18,"MMM-AAAA") -> août-2018 | D18: =GETPIVOTDATA("[Measures].["&D$9&"]",PivotTable!$B$3,"[Dates].[MMM-YYYY]","[Dates].[MMM-YYYY].&["&$C18&"]") -> 25905552654 | E18: =GETPIVOTDATA("[Measures].["&E$9&"]",PivotTable!$B$3,"[Dates].[MMM-YYYY]","[Dates].[MMM-YYYY].&["&$C18&"]") -> 4.3870447e+09 | F18: =E18/D18 -> 0.16934766 | G18: =GETPIVOTDATA("[Measures].["&G$9&"]",PivotTable!$B$3,"[Dates].[MMM-YYYY]","[Dates].[MMM-YYYY].&["&$C18&"]") -> 1071 | H18: =GETPIVOTDATA("[Measures].["&H$9&"]",PivotTable!$B$3,"[Dates].[MMM-YYYY]","[Dates].[MMM-YYYY].&["&$C18&"]") -> 246 | K18: =IFERROR(GETPIVOTDATA("[Measures].[Provision]",PivotTable!$B$3,"[Dates].[MMM-YYYY]","[Dates].[MMM-YYYY].&["&$C18&"]","[Creancedata].[SEGMENT1]","[Creancedata].[SEGMENT1].&["&K$11&"]"),0)/1000000 -> 523.12104 | L18: =IFERROR(GETPIVOTDATA("[Measures].[Provision]",PivotTable!$B$3,"[Dates].[MMM-YYYY]","[Dates].[MMM-YYYY].&["&$C18&"]","[Creancedata].[SEGMENT1]","[Creancedata].[SEGMENT1].&["&L$11&"]"),0)/1000000 -> 197.04526 | M18: =IFERROR(GETPIVOTDATA("[Measures].[Provision]",PivotTable!$B$3,"[Dates].[MMM-YYYY]","[Dates].[MMM-YYYY].&["&$C18&"]","[Creancedata].[SEGMENT1]","[Creancedata].[SEGMENT1].&["&M$11&"]"),0)/1000000 -> 179.55331 | N18: =IFERROR(GETPIVOTDATA("[Measures].[Provision]",PivotTable!$B$3,"[Dates].[MMM-YYYY]","[Dates].[MMM-YYYY].&["&$C18&"]","[Creancedata].[SEGMENT1]","[Creancedata].[SEGMENT1].&["&N$11&"]"),0)/1000000 -> 3357.8818 | O18: =IFERROR(GETPIVOTDATA("[Measures].[Provision]",PivotTable!$B$3,"[Dates].[MMM-YYYY]","[Dates].[MMM-YYYY].&["&$C18&"]","[Creancedata].[SEGMENT1]","[Creancedata].[SEGMENT1].&["&O$11&"]"),0)/1000000 -> 37.361417 | P18: =IFERROR(GETPIVOTDATA("[Measures].[Provision]",PivotTable!$B$3,"[Dates].[MMM-YYYY]","[Dates].[MMM-YYYY].&["&$C18&"]","[Creancedata].[SEGMENT1]","[Creancedata].[SEGMENT1].&["&P$11&"]"),0)/1000000 -> 92.081864 | R18: =E18/1000000 -> 4387.0447 | V18: =V17+1 -> 13 | W18: =TEXT(X18,"MMM-AAAA") -> févr-2019 | X18: 43524
A19: =1+A18 -> 7 | B19: =EOMONTH(B20,-1) -> 43373 | C19: =TEXT(B19,"MMM-AAAA") -> sept-2018 | D19: =GETPIVOTDATA("[Measures].["&D$9&"]",PivotTable!$B$3,"[Dates].[MMM-YYYY]","[Dates].[MMM-YYYY].&["&$C19&"]") -> 28526655075 | E19: =GETPIVOTDATA("[Measures].["&E$9&"]",PivotTable!$B$3,"[Dates].[MMM-YYYY]","[Dates].[MMM-YYYY].&["&$C19&"]") -> 4.9008743e+09 | F19: =E19/D19 -> 0.17179982 | G19: =GETPIVOTDATA("[Measures].["&G$9&"]",PivotTable!$B$3,"[Dates].[MMM-YYYY]","[Dates].[MMM-YYYY].&["&$C19&"]") -> 1221 | H19: =GETPIVOTDATA("[Measures].["&H$9&"]",PivotTable!$B$3,"[Dates].[MMM-YYYY]","[Dates].[MMM-YYYY].&["&$C19&"]") -> 276 | K19: =IFERROR(GETPIVOTDATA("[Measures].[Provision]",PivotTable!$B$3,"[Dates].[MMM-YYYY]","[Dates].[MMM-YYYY].&["&$C19&"]","[Creancedata].[SEGMENT1]","[Creancedata].[SEGMENT1].&["&K$11&"]"),0)/1000000 -> 527.83308 | L19: =IFERROR(GETPIVOTDATA("[Measures].[Provision]",PivotTable!$B$3,"[Dates].[MMM-YYYY]","[Dates].[MMM-YYYY].&["&$C19&"]","[Creancedata].[SEGMENT1]","[Creancedata].[SEGMENT1].&["&L$11&"]"),0)/1000000 -> 62.65004 | M19: =IFERROR(GETPIVOTDATA("[Measures].[Provision]",PivotTable!$B$3,"[Dates].[MMM-YYYY]","[Dates].[MMM-YYYY].&["&$C19&"]","[Creancedata].[SEGMENT1]","[Creancedata].[SEGMENT1].&["&M$11&"]"),0)/1000000 -> 282.54012 | N19: =IFERROR(GETPIVOTDATA("[Measures].[Provision]",PivotTable!$B$3,"[Dates].[MMM-YYYY]","[Dates].[MMM-YYYY].&["&$C19&"]","[Creancedata].[SEGMENT1]","[Creancedata].[SEGMENT1].&["&N$11&"]"),0)/1000000 -> 3833.1339 | O19: =IFERROR(GETPIVOTDATA("[Measures].[Provision]",PivotTable!$B$3,"[Dates].[MMM-YYYY]","[Dates].[MMM-YYYY].&["&$C19&"]","[Creancedata].[SEGMENT1]","[Creancedata].[SEGMENT1].&["&O$11&"]"),0)/1000000 -> 50.804413 | P19: =IFERROR(GETPIVOTDATA("[Measures].[Provision]",PivotTable!$B$3,"[Dates].[MMM-YYYY]","[Dates].[MMM-YYYY].&["&$C19&"]","[Creancedata].[SEGMENT1]","[Creancedata].[SEGMENT1].&["&P$11&"]"),0)/1000000 -> 143.91274 | R19: =E19/1000000 -> 4900.8743 | V19: =V18+1 -> 14 | W19: =TEXT(X19,"MMM-AAAA") -> mars-2019 | X19: 43555
A20: =1+A19 -> 8 | B20: =EOMONTH(B21,-1) -> 43404 | C20: =TEXT(B20,"MMM-AAAA") -> oct-2018 | D20: =GETPIVOTDATA("[Measures].["&D$9&"]",PivotTable!$B$3,"[Dates].[MMM-YYYY]","[Dates].[MMM-YYYY].&["&$C20&"]") -> 31166960023 | E20: =GETPIVOTDATA("[Measures].["&E$9&"]",PivotTable!$B$3,"[Dates].[MMM-YYYY]","[Dates].[MMM-YYYY].&["&$C20&"]") -> 5.2025751e+09 | F20: =E20/D20 -> 0.16692597 | G20: =GETPIVOTDATA("[Measures].["&G$9&"]",PivotTable!$B$3,"[Dates].[MMM-YYYY]","[Dates].[MMM-YYYY].&["&$C20&"]") -> 1397 | H20: =GETPIVOTDATA("[Measures].["&H$9&"]",PivotTable!$B$3,"[Dates].[MMM-YYYY]","[Dates].[MMM-YYYY].&["&$C20&"]") -> 321 | K20: =IFERROR(GETPIVOTDATA("[Measures].[Provision]",PivotTable!$B$3,"[Dates].[MMM-YYYY]","[Dates].[MMM-YYYY].&["&$C20&"]","[Creancedata].[SEGMENT1]","[Creancedata].[SEGMENT1].&["&K$11&"]"),0)/1000000 -> 62.371349 | L20: =IFERROR(GETPIVOTDATA("[Measures].[Provision]",PivotTable!$B$3,"[Dates].[MMM-YYYY]","[Dates].[MMM-YYYY].&["&$C20&"]","[Creancedata].[SEGMENT1]","[Creancedata].[SEGMENT1].&["&L$11&"]"),0)/1000000 -> 85.132918 | M20: =IFERROR(GETPIVOTDATA("[Measures].[Provision]",PivotTable!$B$3,"[Dates].[MMM-YYYY]","[Dates].[MMM-YYYY].&["&$C20&"]","[Creancedata].[SEGMENT1]","[Creancedata].[SEGMENT1].&["&M$11&"]"),0)/1000000 -> 202.85723 | N20: =IFERROR(GETPIVOTDATA("[Measures].[Provision]",PivotTable!$B$3,"[Dates].[MMM-YYYY]","[Dates].[MMM-YYYY].&["&$C20&"]","[Creancedata].[SEGMENT1]","[Creancedata].[SEGMENT1].&["&N$11&"]"),0)/1000000 -> 4513.5664 | O20: =IFERROR(GETPIVOTDATA("[Measures].[Provision]",PivotTable!$B$3,"[Dates].[MMM-YYYY]","[Dates].[MMM-YYYY].&["&$C20&"]","[Creancedata].[SEGMENT1]","[Creancedata].[SEGMENT1].&["&O$11&"]"),0)/1000000 -> 106.80536 | P20: =IFERROR(GETPIVOTDATA("[Measures].[Provision]",PivotTable!$B$3,"[Dates].[MMM-YYYY]","[Dates].[MMM-YYYY].&["&$C20&"]","[Creancedata].[SEGMENT1]","[Creancedata].[SEGMENT1].&["&P$11&"]"),0)/1000000 -> 231.84188 | R20: =E20/1000000 -> 5202.5751
A21: =1+A20 -> 9 | B21: =EOMONTH(B22,-1) -> 43434 | C21: =TEXT(B21,"MMM-AAAA") -> nov-2018 | D21: =GETPIVOTDATA("[Measures].["&D$9&"]",PivotTable!$B$3,"[Dates].[MMM-YYYY]","[Dates].[MMM-YYYY].&["&$C21&"]") -> 39578031867 | E21: =GETPIVOTDATA("[Measures].["&E$9&"]",PivotTable!$B$3,"[Dates].[MMM-YYYY]","[Dates].[MMM-YYYY].&["&$C21&"]") -> 6.5172784e+09 | F21: =E21/D21 -> 0.16466909 | G21: =GETPIVOTDATA("[Measures].["&G$9&"]",PivotTable!$B$3,"[Dates].[MMM-YYYY]","[Dates].[MMM-YYYY].&["&$C21&"]") -> 1583 | H21: =GETPIVOTDATA("[Measures].["&H$9&"]",PivotTable!$B$3,"[Dates].[MMM-YYYY]","[Dates].[MMM-YYYY].&["&$C21&"]") -> 368 | K21: =IFERROR(GETPIVOTDATA("[Measures].[Provision]",PivotTable!$B$3,"[Dates].[MMM-YYYY]","[Dates].[MMM-YYYY].&["&$C21&"]","[Creancedata].[SEGMENT1]","[Creancedata].[SEGMENT1].&["&K$11&"]"),0)/1000000 -> 96.926451 | L21: =IFERROR(GETPIVOTDATA("[Measures].[Provision]",PivotTable!$B$3,"[Dates].[MMM-YYYY]","[Dates].[MMM-YYYY].&["&$C21&"]","[Creancedata].[SEGMENT1]","[Creancedata].[SEGMENT1].&["&L$11&"]"),0)/1000000 -> 59.594742 | M21: =IFERROR(GETPIVOTDATA("[Measures].[Provision]",PivotTable!$B$3,"[Dates].[MMM-YYYY]","[Dates].[MMM-YYYY].&["&$C21&"]","[Creancedata].[SEGMENT1]","[Creancedata].[SEGMENT1].&["&M$11&"]"),0)/1000000 -> 242.43807 | N21: =IFERROR(GETPIVOTDATA("[Measures].[Provision]",PivotTable!$B$3,"[Dates].[MMM-YYYY]","[Dates].[MMM-YYYY].&["&$C21&"]","[Creancedata].[SEGMENT1]","[Creancedata].[SEGMENT1].&["&N$11&"]"),0)/1000000 -> 5643.0845 | O21: =IFERROR(GETPIVOTDATA("[Measures].[Provision]",PivotTable!$B$3,"[Dates].[MMM-YYYY]","[Dates].[MMM-YYYY].&["&$C21&"]","[Creancedata].[SEGMENT1]","[Creancedata].[SEGMENT1].&["&O$11&"]"),0)/1000000 -> 280.44247 | P21: =IFERROR(GETPIVOTDATA("[Measures].[Provision]",PivotTable!$B$3,"[Dates].[MMM-YYYY]","[Dates].[MMM-YYYY].&["&$C21&"]","[Creancedata].[SEGMENT1]","[Creancedata].[SEGMENT1].&["&P$11&"]"),0)/1000000 -> 194.7921 | R21: =E21/1000000 -> 6517.2784
A22: =1+A21 -> 10 | B22: =EOMONTH(B23,-1) -> 43465 | C22: =TEXT(B22,"MMM-AAAA") -> déc-2018 | D22: =GETPIVOTDATA("[Measures].["&D$9&"]",PivotTable!$B$3,"[Dates].[MMM-YYYY]","[Dates].[MMM-YYYY].&["&$C22&"]") -> 49388709579 | E22: =GETPIVOTDATA("[Measures].["&E$9&"]",PivotTable!$B$3,"[Dates].[MMM-YYYY]","[Dates].[MMM-YYYY].&["&$C22&"]") -> 7.8603606e+09 | F22: =E22/D22 -> 0.15915299 | G22: =GETPIVOTDATA("[Measures].["&G$9&"]",PivotTable!$B$3,"[Dates].[MMM-YYYY]","[Dates].[MMM-YYYY].&["&$C22&"]") -> 1868 | H22: =GETPIVOTDATA("[Measures].["&H$9&"]",PivotTable!$B$3,"[Dates].[MMM-YYYY]","[Dates].[MMM-YYYY].&["&$C22&"]") -> 435 | K22: =IFERROR(GETPIVOTDATA("[Measures].[Provision]",PivotTable!$B$3,"[Dates].[MMM-YYYY]","[Dates].[MMM-YYYY].&["&$C22&"]","[Creancedata].[SEGMENT1]","[Creancedata].[SEGMENT1].&["&K$11&"]"),0)/1000000 -> 139.81633 | L22: =IFERROR(GETPIVOTDATA("[Measures].[Provision]",PivotTable!$B$3,"[Dates].[MMM-YYYY]","[Dates].[MMM-YYYY].&["&$C22&"]","[Creancedata].[SEGMENT1]","[Creancedata].[SEGMENT1].&["&L$11&"]"),0)/1000000 -> 61.991233 | M22: =IFERROR(GETPIVOTDATA("[Measures].[Provision]",PivotTable!$B$3,"[Dates].[MMM-YYYY]","[Dates].[MMM-YYYY].&["&$C22&"]","[Creancedata].[SEGMENT1]","[Creancedata].[SEGMENT1].&["&M$11&"]"),0)/1000000 -> 428.03974 | N22: =IFERROR(GETPIVOTDATA("[Measures].[Provision]",PivotTable!$B$3,"[Dates].[MMM-YYYY]","[Dates].[MMM-YYYY].&["&$C22&"]","[Creancedata].[SEGMENT1]","[Creancedata].[SEGMENT1].&["&N$11&"]"),0)/1000000 -> 6379.2236 | O22: =IFERROR(GETPIVOTDATA("[Measures].[Provision]",PivotTable!$B$3,"[Dates].[MMM-YYYY]","[Dates].[MMM-YYYY].&["&$C22&"]","[Creancedata].[SEGMENT1]","[Creancedata].[SEGMENT1].&["&O$11&"]"),0)/1000000 -> 635.23403 | P22: =IFERROR(GETPIVOTDATA("[Measures].[Provision]",PivotTable!$B$3,"[Dates].[MMM-YYYY]","[Dates].[MMM-YYYY].&["&$C22&"]","[Creancedata].[SEGMENT1]","[Creancedata].[SEGMENT1].&["&P$11&"]"),0)/1000000 -> 216.05576 | R22: =E22/1000000 -> 7860.3606
A23: =1+A22 -> 11 | B23: =EOMONTH(B24,-1) -> 43496 | C23: =TEXT(B23,"MMM-AAAA") -> janv-2019 | D23: =GETPIVOTDATA("[Measures].["&D$9&"]",PivotTable!$B$3,"[Dates].[MMM-YYYY]","[Dates].[MMM-YYYY].&["&$C23&"]") -> 68722623753 | E23: =GETPIVOTDATA("[Measures].["&E$9&"]",PivotTable!$B$3,"[Dates].[MMM-YYYY]","[Dates].[MMM-YYYY].&["&$C23&"]") -> 1.0133759e+10 | F23: =E23/D23 -> 0.14745885 | G23: =GETPIVOTDATA("[Measures].["&G$9&"]",PivotTable!$B$3,"[Dates].[MMM-YYYY]","[Dates].[MMM-YYYY].&["&$C23&"]") -> 2153 | H23: =GETPIVOTDATA("[Measures].["&H$9&"]",PivotTable!$B$3,"[Dates].[MMM-YYYY]","[Dates].[MMM-YYYY].&["&$C23&"]") -> 524 | K23: =IFERROR(GETPIVOTDATA("[Measures].[Provision]",PivotTable!$B$3,"[Dates].[MMM-YYYY]","[Dates].[MMM-YYYY].&["&$C23&"]","[Creancedata].[SEGMENT1]","[Creancedata].[SEGMENT1].&["&K$11&"]"),0)/1000000 -> 167.23062 | L23: =IFERROR(GETPIVOTDATA("[Measures].[Provision]",PivotTable!$B$3,"[Dates].[MMM-YYYY]","[Dates].[MMM-YYYY].&["&$C23&"]","[Creancedata].[SEGMENT1]","[Creancedata].[SEGMENT1].&["&L$11&"]"),0)/1000000 -> 221.96598 | M23: =IFERROR(GETPIVOTDATA("[Measures].[Provision]",PivotTable!$B$3,"[Dates].[MMM-YYYY]","[Dates].[MMM-YYYY].&["&$C23&"]","[Creancedata].[SEGMENT1]","[Creancedata].[SEGMENT1].&["&M$11&"]"),0)/1000000 -> 540.83798 | N23: =IFERROR(GETPIVOTDATA("[Measures].[Provision]",PivotTable!$B$3,"[Dates].[MMM-YYYY]","[Dates].[MMM-YYYY].&["&$C23&"]","[Creancedata].[SEGMENT1]","[Creancedata].[SEGMENT1].&["&N$11&"]"),0)/1000000 -> 7565.386 | O23: =IFERROR(GETPIVOTDATA("[Measures].[Provision]",PivotTable!$B$3,"[Dates].[MMM-YYYY]","[Dates].[MMM-YYYY].&["&$C23&"]","[Creancedata].[SEGMENT1]","[Creancedata].[SEGMENT1].&["&O$11&"]"),0)/1000000 -> 1366.2501 | P23: =IFERROR(GETPIVOTDATA("[Measures].[Provision]",PivotTable!$B$3,"[Dates].[MMM-YYYY]","[Dates].[MMM-YYYY].&["&$C23&"]","[Creancedata].[SEGMENT1]","[Creancedata].[SEGMENT1].&["&P$11&"]"),0)/1000000 -> 272.08812 | R23: =E23/1000000 -> 10133.759
A24: =1+A23 -> 12 | B24: =C6 -> 43524 | C24: =TEXT(B24,"MMM-AAAA") -> févr-2019 | D24: =GETPIVOTDATA("[Measures].["&D$9&"]",PivotTable!$B$3,"[Dates].[MMM-YYYY]","[Dates].[MMM-YYYY].&["&$C24&"]") -> 79783809966 | E24: =GETPIVOTDATA("[Measures].["&E$9&"]",PivotTable!$B$3,"[Dates].[MMM-YYYY]","[Dates].[MMM-YYYY].&["&$C24&"]") -> 1.1461991e+10 | F24: =E24/D24 -> 0.14366312 | G24: =GETPIVOTDATA("[Measures].["&G$9&"]",PivotTable!$B$3,"[Dates].[MMM-YYYY]","[Dates].[MMM-YYYY].&["&$C24&"]") -> 2457 | H24: =GETPIVOTDATA("[Measures].["&H$9&"]",PivotTable!$B$3,"[Dates].[MMM-YYYY]","[Dates].[MMM-YYYY].&["&$C24&"]") -> 578 | K24: =IFERROR(GETPIVOTDATA("[Measures].[Provision]",PivotTable!$B$3,"[Dates].[MMM-YYYY]","[Dates].[MMM-YYYY].&["&$C24&"]","[Creancedata].[SEGMENT1]","[Creancedata].[SEGMENT1].&["&K$11&"]"),0)/1000000 -> 205.25901 | L24: =IFERROR(GETPIVOTDATA("[Measures].[Provision]",PivotTable!$B$3,"[Dates].[MMM-YYYY]","[Dates].[MMM-YYYY].&["&$C24&"]","[Creancedata].[SEGMENT1]","[Creancedata].[SEGMENT1].&["&L$11&"]"),0)/1000000 -> 233.56222 | M24: =IFERROR(GETPIVOTDATA("[Measures].[Provision]",PivotTable!$B$3,"[Dates].[MMM-YYYY]","[Dates].[MMM-YYYY].&["&$C24&"]","[Creancedata].[SEGMENT1]","[Creancedata].[SEGMENT1].&["&M$11&"]"),0)/1000000 -> 718.34295 | N24: =IFERROR(GETPIVOTDATA("[Measures].[Provision]",PivotTable!$B$3,"[Dates].[MMM-YYYY]","[Dates].[MMM-YYYY].&["&$C24&"]","[Creancedata].[SEGMENT1]","[Creancedata].[SEGMENT1].&["&N$11&"]"),0)/1000000 -> 8411.7575 | O24: =IFERROR(GETPIVOTDATA("[Measures].[Provision]",PivotTable!$B$3,"[Dates].[MMM-YYYY]","[Dates].[MMM-YYYY].&["&$C24&"]","[Creancedata].[SEGMENT1]","[Creancedata].[SEGMENT1].&["&O$11&"]"),0)/1000000 -> 1370.499 | P24: =IFERROR(GETPIVOTDATA("[Measures].[Provision]",PivotTable!$B$3,"[Dates].[MMM-YYYY]","[Dates].[MMM-YYYY].&["&$C24&"]","[Creancedata].[SEGMENT1]","[Creancedata].[SEGMENT1].&["&P$11&"]"),0)/1000000 -> 522.57014 | R24: =E24/1000000 -> 11461.991
B62: Overview KPI | D62: =TEXT(C6,"MMM-AAAA") -> févr-2019
D63: 0
B64: Créances | D64: =D24 -> 79783809966 | E64: =D23 -> 68722623753 | F64: =D64/E64-1 -> 0.16095407
B65: Provision | D65: =E24 -> 1.1461991e+10 | E65: =E23 -> 1.0133759e+10 | F65: =D65/E65-1 -> 0.13107001
B66: % Dépreciation | D66: =D65/D64 -> 0.14366312
B67: # Nb Factures | D67: =G24 -> 2457
B68: # Nb Clients | D68: =H24 -> 578
B70: Waterfall Chart
C72: Total | D72: Overdue 1-30 jrs | E72: Overdue 31-60 jrs | F72: Overdue 61-90 jrs | G72: Overdue 91-120 jrs | H72: Overdue 120 + jrs
B73: Actuals | C73: =SUM(D73:H73) -> 1.0240019e+10 | D73: =IFERROR(GETPIVOTDATA("[Measures].[Provision]",PivotTable!$M$3,"[Dates].[MMM-YYYY]","[Dates].[MMM-YYYY].&["&$D$62&"]","[Date Range].[DelaiGroup]","[Date Range].[DelaiGroup].&["&D72&"]"),0) -> 1.6343193e+09 | E73: =IFERROR(GETPIVOTDATA("[Measures].[Provision]",PivotTable!$M$3,"[Dates].[MMM-YYYY]","[Dates].[MMM-YYYY].&["&$D$62&"]","[Date Range].[DelaiGroup]","[Date Range].[DelaiGroup].&["&E72&"]"),0) -> 0 | F73: =IFERROR(GETPIVOTDATA("[Measures].[Provision]",PivotTable!$M$3,"[Dates].[MMM-YYYY]","[Dates].[MMM-YYYY].&["&$D$62&"]","[Date Range].[DelaiGroup]","[Date Range].[DelaiGroup].&["&F72&"]"),0) -> 1.4315681e+09 | G73: =IFERROR(GETPIVOTDATA("[Measures].[Provision]",PivotTable!$M$3,"[Dates].[MMM-YYYY]","[Dates].[MMM-YYYY].&["&$D$62&"]","[Date Range].[DelaiGroup]","[Date Range].[DelaiGroup].&["&G72&"]"),0) -> 1.6797696e+09 | H73: =IFERROR(GETPIVOTDATA("[Measures].[Provision]",PivotTable!$M$3,"[Dates].[MMM-YYYY]","[Dates].[MMM-YYYY].&["&$D$62&"]","[Date Range].[DelaiGroup]","[Date Range].[DelaiGroup].&["&H72&"]"),0) -> 5.4943623e+09
B74: Invisible | C74: 0 | D74: 0 | E74: =SUM($D73:D73) -> 1.6343193e+09 | F74: =SUM($D73:E73) -> 1.6343193e+09 | G74: =SUM($D73:F73) -> 3.0658874e+09 | H74: =SUM($D73:G73) -> 4.745657e+09
B76: Sorted Bar Chart
B78: Department | C78: Provision | D78: No. | E78: Dummy Value | F78: Position | G78: Departments sorted | H78: Value
B79: Segment 1 | C79: =K24 -> 205.25901 | D79: 1 | E79: =C79+D79/1000000 -> 205.25901 | F79: =MATCH(SMALL($E$79:$E$84,D79),$E$79:$E$84,0) -> 1 | G79: =INDEX($B$79:$B$84,F79,1) -> Segment 1 | H79: =INDEX($C$79:$C$84,F79,1) -> 205.25901
B80: Segment 2 | C80: =L24 -> 233.56222 | D80: 2 | E80: =C80+D80/1000000 -> 233.56223 | F80: =MATCH(SMALL($E$79:$E$84,D80),$E$79:$E$84,0) -> 2 | G80: =INDEX($B$79:$B$84,F80,1) -> Segment 2 | H80: =INDEX($C$79:$C$84,F80,1) -> 233.56222
B81: Segment 3 | C81: =M24 -> 718.34295 | D81: 3 | E81: =C81+D81/1000000 -> 718.34295 | F81: =MATCH(SMALL($E$79:$E$84,D81),$E$79:$E$84,0) -> 6 | G81: =INDEX($B$79:$B$84,F81,1) -> Segment 6 | H81: =INDEX($C$79:$C$84,F81,1) -> 522.57014
B82: Segment 4 | C82: =N24 -> 8411.7575 | D82: 4 | E82: =C82+D82/1000000 -> 8411.7575 | F82: =MATCH(SMALL($E$79:$E$84,D82),$E$79:$E$84,0) -> 3 | G82: =INDEX($B$79:$B$84,F82,1) -> Segment 3 | H82: =INDEX($C$79:$C$84,F82,1) -> 718.34295
B83: Segment 5 | C83: =O24 -> 1370.499 | D83: 5 | E83: =C83+D83/1000000 -> 1370.499 | F83: =MATCH(SMALL($E$79:$E$84,D83),$E$79:$E$84,0) -> 5 | G83: =INDEX($B$79:$B$84,F83,1) -> Segment 5 | H83: =INDEX($C$79:$C$84,F83,1) -> 1370.499
...

Sheet PivotTable
B3: Row Labels | C3: RAP | D3: RAP PM | E3: Provision | F3: Provision PM | G3: #Nb Factures | H3: NbClient | M3: Row Labels | N3: RAP | O3: RAP PM | P3: Provision | Q3: Provision PM | R3: #Nb Factures | S3: NbClient
B4: sept-2018 | C4: 28526655075 | D4: 25905552654 | E4: 4.9008743e+09 | F4: 4.3870447e+09 | G4: 1221 | H4: 276 | M4: sept-2018 | N4: 28526655075 | O4: 25905552654 | P4: 4.9008743e+09 | Q4: 4.3870447e+09 | R4: 1221 | S4: 276
B5: Segment 1 | C5: 2791586766 | D5: 4037890877 | E5: 5.2783308e+08 | F5: 5.2312104e+08 | G5: 69 | H5: 13 | M5: Overdue 120 + jrs | N5: 8487046924 | O5: 7842249138 | P5: 2.5461141e+09 | Q5: 2.3526747e+09 | R5: 421 | S5: 116
B6: Segment 2 | C6: 612062370 | D6: 787644714 | E6: 62650040 | F6: 1.9704526e+08 | G6: 66 | H6: 29 | K6: Overdue 120 + jrs | M6: Overdue 1-30 jrs | N6: 6337780053 | O6: 5865706077 | P6: 5.070224e+08 | Q6: 4.6925649e+08 | R6: 260 | S6: 244 | V6: Overdue 1-30 jrs | W6: Overdue 31-60 jrs | X6: Overdue 61-90 jrs | Y6: Overdue 91-120 jrs | Z6: Overdue 120 + jrs
B7: Segment 3 | C7: 2018563884 | D7: 945940162 | E7: 2.8254012e+08 | F7: 1.7955331e+08 | G7: 24 | H7: 8 | K7: Overdue 1-30 jrs | M7: Overdue 31-60 jrs | N7: 5335489079 | O7: 3447990023 | P7: 5.1220695e+08 | Q7: 3.3100704e+08 | R7: 228 | S7: 215
B8: Segment 4 | C8: 21876496904 | D8: 19031891004 | E8: 3.8331339e+09 | F8: 3.3578818e+09 | G8: 1022 | H8: 214 | K8: Overdue 31-60 jrs | M8: Overdue 61-90 jrs | N8: 3397925335 | O8: 6263688144 | P8: 4.2134274e+08 | Q8: 7.7669733e+08 | R8: 165 | S8: 160
B9: Segment 5 | C9: 500904804 | D9: 440730564 | E9: 50804413 | F9: 37361417 | G9: 10 | H9: 4 | K9: Overdue 61-90 jrs | M9: Overdue 91-120 jrs | N9: 4968413684 | O9: 2485919272 | P9: 9.1418812e+08 | Q9: 4.5740915e+08 | R9: 147 | S9: 138
B10: Segment 6 | C10: 727040347 | D10: 661455333 | E10: 1.4391274e+08 | F10: 92081864 | G10: 30 | H10: 8 | K10: Overdue 91-120 jrs | M10: oct-2018 | N10: 31166960023 | O10: 28526655075 | P10: 5.2025751e+09 | Q10: 4.9008743e+09 | R10: 1397 | S10: 321
B11: oct-2018 | C11: 31166960023 | D11: 28526655075 | E11: 5.2025751e+09 | F11: 4.9008743e+09 | G11: 1397 | H11: 321 | M11: Overdue 120 + jrs | N11: 9832167630 | O11: 8487046924 | P11: 2.9496503e+09 | Q11: 2.5461141e+09 | R11: 498 | S11: 129
B12: Segment 1 | C12: 259565836 | D12: 2791586766 | E12: 62371349 | F12: 5.2783308e+08 | G12: 70 | H12: 13 | M12: Overdue 1-30 jrs | N12: 9171667695 | O12: 6337780053 | P12: 7.3373342e+08 | Q12: 5.070224e+08 | R12: 305 | S12: 297
B13: Segment 2 | C13: 649283758 | D13: 612062370 | E13: 85132918 | F13: 62650040 | G13: 86 | H13: 34 | M13: Overdue 31-60 jrs | N13: 4948506913 | O13: 5335489079 | P13: 4.7505666e+08 | Q13: 5.1220695e+08 | R13: 258 | S13: 236
B14: Segment 3 | C14: 1949197454 | D14: 2018563884 | E14: 2.0285723e+08 | F14: 2.8254012e+08 | G14: 22 | H14: 8 | M14: Overdue 61-90 jrs | N14: 4722581596 | O14: 3397925335 | P14: 5.8560012e+08 | Q14: 4.2134274e+08 | R14: 202 | S14: 193
B15: Segment 4 | C15: 25471941623 | D15: 21876496904 | E15: 4.5135664e+09 | F15: 3.8331339e+09 | G15: 1167 | H15: 249 | M15: Overdue 91-120 jrs | N15: 2492036189 | O15: 4968413684 | P15: 4.5853466e+08 | Q15: 9.1418812e+08 | R15: 134 | S15: 133
B16: Segment 5 | C16: 993960630 | D16: 500904804 | E16: 1.0680536e+08 | F16: 50804413 | G16: 16 | H16: 7 | M16: nov-2018 | N16: 39578031867 | O16: 31166960023 | P16: 6.5172784e+09 | Q16: 5.2025751e+09 | R16: 1583 | S16: 368
B17: Segment 6 | C17: 1843010722 | D17: 727040347 | E17: 2.3184188e+08 | F17: 1.4391274e+08 | G17: 36 | H17: 10 | M17: Overdue 120 + jrs | N17: 11753167185 | O17: 9832167630 | P17: 3.5259502e+09 | Q17: 2.9496503e+09 | R17: 575 | S17: 137
B18: nov-2018 | C18: 39578031867 | D18: 31166960023 | E18: 6.5172784e+09 | F18: 5.2025751e+09 | G18: 1583 | H18: 368 | M18: Overdue 1-30 jrs | N18: 12446497918 | O18: 9171667695 | P18: 9.9571983e+08 | Q18: 7.3373342e+08 | R18: 330 | S18: 325
B19: Segment 1 | C19: 627253374 | D19: 259565836 | E19: 96926451 | F19: 62371349 | G19: 79 | H19: 13 | M19: Overdue 31-60 jrs | N19: 6744809197 | O19: 4948506913 | P19: 6.4750168e+08 | Q19: 4.7505666e+08 | R19: 273 | S19: 265
B20: Segment 2 | C20: 457516042 | D20: 649283758 | E20: 59594742 | F20: 85132918 | G20: 88 | H20: 42 | M20: Overdue 61-90 jrs | N20: 4007798499 | O20: 4722581596 | P20: 4.9696701e+08 | Q20: 5.8560012e+08 | R20: 224 | S20: 208
B21: Segment 3 | C21: 1993614550 | D21: 1949197454 | E21: 2.4243807e+08 | F21: 2.0285723e+08 | G21: 25 | H21: 10 | M21: Overdue 91-120 jrs | N21: 4625759068 | O21: 2492036189 | P21: 8.5113967e+08 | Q21: 4.5853466e+08 | R21: 181 | S21: 173
B22: Segment 4 | C22: 31901776945 | D22: 25471941623 | E22: 5.6430845e+09 | F22: 4.5135664e+09 | G22: 1331 | H22: 280 | M22: mars-2019 | N22: 83038654979 | O22: 79783809966 | P22: 1.3833799e+10 | Q22: 1.1461991e+10 | R22: 2622 | S22: 614
B23: Segment 5 | C23: 2631164772 | D23: 993960630 | E23: 2.8044247e+08 | F23: 1.0680536e+08 | G23: 29 | H23: 13 | M23: Not Overdue | O23: 20366191136 | Q23: 1.2219715e+09
B24: Segment 6 | C24: 1966706184 | D24: 1843010722 | E24: 1.947921e+08 | F24: 2.3184188e+08 | G24: 31 | H24: 10 | M24: Overdue 120 + jrs | N24: 24536129357 | O24: 18314541009 | P24: 7.3608388e+09 | Q24: 5.4943623e+09 | R24: 1032 | S24: 236
B25: mars-2019 | C25: 83038654979 | D25: 79783809966 | E25: 1.3833799e+10 | F25: 1.1461991e+10 | G25: 2622 | H25: 614 | M25: Overdue 1-30 jrs | N25: 31099654875 | O25: 20428991339 | P25: 2487972390 | Q25: 1.6343193e+09 | R25: 899 | S25: 554
B26: Segment 1 | C26: 1269626528 | D26: 1196777958 | E26: 2.8245383e+08 | F26: 2.0525901e+08 | G26: 116 | H26: 21 | M26: Overdue 61-90 jrs | N26: 17619010049 | O26: 11544903748 | P26: 2.1847572e+09 | Q26: 1.4315681e+09 | R26: 389 | S26: 380
B27: Segment 2 | C27: 2810745198 | D27: 2549472084 | E27: 3.3144739e+08 | F27: 2.3356222e+08 | G27: 130 | H27: 56 | M27: Overdue 91-120 jrs | N27: 9783860698 | O27: 9129182734 | P27: 1.8002304e+09 | Q27: 1.6797696e+09 | R27: 302 | S27: 282
B28: Segment 3 | C28: 6616034907 | D28: 6972012938 | E28: 8.9687882e+08 | F28: 7.1834295e+08 | G28: 53 | H28: 19 | M28: mars-2018 | N28: 18835091761 | O28: 17558129114 | P28: 3.186612e+09 | Q28: 2.6021263e+09 | R28: 450 | S28: 140
B29: Segment 4 | C29: 50388586429 | D29: 50620649456 | E29: 9.4333744e+09 | F29: 8.4117575e+09 | G29: 2156 | H29: 462 | M29: Not Overdue | O29: 3287024993 | Q29: 1.972215e+08
B30: Segment 5 | C30: 16770474577 | D30: 13789298482 | E30: 2.0439422e+09 | F30: 1.370499e+09 | G30: 121 | H30: 40 | M30: Overdue 120 + jrs | N30: 6270204696 | O30: 3636958907 | P30: 1.8810614e+09 | Q30: 1.0910877e+09 | R30: 111 | S30: 46
B31: Segment 6 | C31: 5183187340 | D31: 4655599048 | E31: 8.4570212e+08 | F31: 5.2257014e+08 | G31: 46 | H31: 16 | M31: Overdue 1-30 jrs | N31: 6792890326 | O31: 5389342995 | P31: 5.4343123e+08 | Q31: 4.3114744e+08 | R31: 231 | S31: 131
B32: mars-2018 | C32: 18835091761 | D32: 17558129114 | E32: 3.186612e+09 | F32: 2.6021263e+09 | G32: 450 | H32: 140 | M32: Overdue 61-90 jrs | N32: 4998801135 | O32: 1372898832 | P32: 6.1985134e+08 | Q32: 1.7023946e+08 | R32: 62 | S32: 62
B33: Segment 1 | C33: 109970426 | D33: 60785868 | E33: 12448358 | F33: 5565705.1 | G33: 15 | H33: 8 | M33: Overdue 91-120 jrs | N33: 773195604 | O33: 3871903387 | P33: 1.4226799e+08 | Q33: 7.1243022e+08 | R33: 46 | S33: 45
B34: Segment 2 | C34: 812230790 | D34: 1125007198 | E34: 79830863 | F34: 2.9447251e+08 | G34: 29 | H34: 13 | M34: mai-2018 | N34: 16198776172 | O34: 22231742939 | P34: 2.7971895e+09 | Q34: 3.8853683e+09 | R34: 670 | S34: 176
B35: Segment 3 | C35: 105918336 | D35: 105909696 | E35: 8473466.9 | F35: 6354581.8 | G35: 2 | H35: 1 | M35: Overdue 120 + jrs | N35: 5285739865 | O35: 6769257144 | P35: 1.585722e+09 | Q35: 2.0307771e+09 | R35: 180 | S35: 57
B36: Segment 4 | C36: 13143893363 | D36: 11436325112 | E36: 1.9202233e+09 | F36: 1.5255373e+09 | G36: 387 | H36: 111 | M36: Overdue 1-30 jrs | N36: 2746347765 | O36: 4139942786 | P36: 2.1970782e+08 | Q36: 3.3119542e+08 | R36: 171 | S36: 161
B37: Segment 6 | C37: 4663078846 | D37: 4830101240 | E37: 1.165636e+09 | F37: 7.7019615e+08 | G37: 17 | H37: 7 | M37: Overdue 31-60 jrs | N37: 3852717568 | O37: 6363093390 | P37: 3.6986089e+08 | Q37: 6.1085697e+08 | R37: 136 | S37: 127
B38: mai-2018 | C38: 16198776172 | D38: 22231742939 | E38: 2.7971895e+09 | F38: 3.8853683e+09 | G38: 670 | H38: 176 | M38: Overdue 61-90 jrs | N38: 2864530635 | P38: 3.552018e+08 | R38: 111 | S38: 100
B39: Segment 1 | C39: 183847948 | D39: 388870750 | E39: 29015150 | F39: 38449908 | G39: 35 | H39: 12 | M39: Overdue 91-120 jrs | N39: 1449440339 | O39: 4959449619 | P39: 2.6669702e+08 | Q39: 9.1253873e+08 | R39: 72 | S39: 71
B40: Segment 2 | C40: 649447082 | D40: 649576412 | E40: 84916265 | F40: 63486014 | G40: 32 | H40: 10 | M40: juin-2018 | N40: 20422167699 | O40: 16198776172 | P40: 3.1561579e+09 | Q40: 2.7971895e+09 | R40: 798 | S40: 196
B41: Segment 3 | C41: 592549260 | D41: 566780928 | E41: 65792731 | F41: 47037168 | G41: 9 | H41: 4 | M41: Overdue 120 + jrs | N41: 4766263439 | O41: 5285739865 | P41: 1.429879e+09 | Q41: 1.585722e+09 | R41: 232 | S41: 72
B42: Segment 4 | C42: 12950967378 | D42: 14707752257 | E42: 2.4277635e+09 | F42: 2.423579e+09 | G42: 580 | H42: 144 | M42: Overdue 1-30 jrs | N42: 6961101864 | O42: 2746347765 | P42: 5.5688815e+08 | Q42: 2.1970782e+08 | R42: 192 | S42: 176
...

Sheet Feuil2
B1: Annee | C1: 2008
B3: Somme de Montant | C3: Column Labels
B4: Row Labels | C4: 1 | D4: 2 | E4: 3 | F4: 4 | G4: 5 | H4: 6 | I4: 7 | J4: 8 | K4: 9 | L4: 10 | M4: 11 | N4: 12 | O4: Grand Total
B5: Not Overdue | D5: 178973263 | O5: 178973263
B6: Overdue 120 + jrs | C6: 43348482 | D6: 7473781 | E6: 71729909 | F6: 31914646 | G6: 334044804 | H6: 43275751 | I6: 239144361 | J6: 46391577 | K6: 25851129 | L6: 37348553 | M6: 289992362 | O6: 1170515355
B7: Overdue 1-30 jrs | C7: 178865631 | D7: 127102047 | E7: 166444643 | F7: 162901357 | G7: 212157439 | H7: 157492072 | I7: 274734664 | J7: 285790714 | K7: 306856908 | L7: 298269157 | M7: 338312672 | N7: 276715603 | O7: 2785642907
B8: Overdue 31-60 jrs | D8: 120930645 | E8: 155170163 | F8: 145201800 | G8: 192832693 | H8: 151296643 | I8: 268095559 | J8: 187116359 | K8: 279833317 | L8: 154838831 | M8: 342589261 | N8: 259881692 | O8: 2257786963
B9: Overdue 61-90 jrs | C9: 40580030 | E9: 59598558 | F9: 137624122 | G9: 184618062 | H9: 150397554 | I9: 163423037 | J9: 151657668 | K9: 162803596 | L9: 142995174 | M9: 332698172 | N9: 250654467 | O9: 1777050440
B10: Overdue 91-120 jrs | C10: 40171423 | D10: 11576192 | E10: 53146483 | F10: 48308233 | G10: 183774853 | H10: 149416684 | I10: 122563479 | J10: 150561124 | K10: 49967586 | L10: 30288484 | M10: 324038112 | N10: 243757998 | O10: 1407570651
B11: Grand Total | C11: 302965566 | D11: 446055928 | E11: 506089756 | F11: 525950158 | G11: 1107427851 | H11: 651878704 | I11: 1067961100 | J11: 821517442 | K11: 825312536 | L11: 663740199 | M11: 1627630579 | N11: 1031009760 | O11: 9577539579

Sheet Sheet1
